Workbook

Sheet Consultazione
B2: ID | C2: ='Elenco Giocatori'!C7 -> Giocatore | D2: ='Elenco Giocatori'!D7 -> Serie | E2: ='Elenco Giocatori'!E7 -> Ruolo | F2: Squadra | G2: ='Elenco Giocatori'!AC7 -> Media | H2: 1 | I2: 2 | J2: 3 | K2: 4 | L2: 5 | M2: 6 | N2: 7 | O2: 8 | P2: 9 | Q2: 10 | R2: 11 | S2: 12 | T2: 13 | U2: 14 | V2: 15 | W2: 16 | X2: 17 | Y2: 18 | Z2: 19
B3: {=_xlfn.XLOOKUP(C3,Disponibili!G:G,Disponibili!F:F)} -> 2 | C3: ='Elenco Giocatori'!C9 -> Marco Vitale | D3: ='Elenco Giocatori'!D9 -> B | E3: ='Elenco Giocatori'!E9 -> A | F3: ='Elenco Giocatori'!F9 -> Akragas | G3: ='Elenco Giocatori'!AC9 -> 5.5 | H3: ='Elenco Giocatori'!H9 -> 5.5 | I3: ='Elenco Giocatori'!I9 | J3: ='Elenco Giocatori'!J9 | K3: ='Elenco Giocatori'!K9 | L3: ='Elenco Giocatori'!L9 | M3: ='Elenco Giocatori'!M9 | N3: ='Elenco Giocatori'!N9 | O3: ='Elenco Giocatori'!O9 | ... Z3: ='Elenco Giocatori'!Z9
B4: {=_xlfn.XLOOKUP(C4,Disponibili!G:G,Disponibili!F:F)} -> 8 | C4: ='Elenco Giocatori'!C15 -> Tomas Bergovic | D4: ='Elenco Giocatori'!D15 -> B | E4: ='Elenco Giocatori'!E15 -> D | F4: ='Elenco Giocatori'!F15 -> Akragas | G4: ='Elenco Giocatori'!AC15 -> 6.375 | H4: ='Elenco Giocatori'!H15 -> 7.1 | I4: ='Elenco Giocatori'!I15 -> 5.65 | J4: ='Elenco Giocatori'!J15 | K4: ='Elenco Giocatori'!K15 | L4: ='Elenco Giocatori'!L15 | M4: ='Elenco Giocatori'!M15 | N4: ='Elenco Giocatori'!N15 | O4: ='Elenco Giocatori'!O15 | ... Z4: ='Elenco Giocatori'!Z15
B5: {=_xlfn.XLOOKUP(C5,Disponibili!G:G,Disponibili!F:F)} -> 26 | C5: ='Elenco Giocatori'!C33 -> Andrea Pallante | D5: ='Elenco Giocatori'!D33 -> B | E5: ='Elenco Giocatori'!E33 -> D | F5: ='Elenco Giocatori'!F33 -> Alessandria | G5: ='Elenco Giocatori'!AC33 -> 5.475 | H5: ='Elenco Giocatori'!H33 -> 5.475 | I5: ='Elenco Giocatori'!I33 | J5: ='Elenco Giocatori'!J33 | K5: ='Elenco Giocatori'!K33 | L5: ='Elenco Giocatori'!L33 | M5: ='Elenco Giocatori'!M33 | N5: ='Elenco Giocatori'!N33 | O5: ='Elenco Giocatori'!O33 | ... Z5: ='Elenco Giocatori'!Z33
B6: {=_xlfn.XLOOKUP(C6,Disponibili!G:G,Disponibili!F:F)} -> 620 | C6: ='Elenco Giocatori'!C562 -> Simone Trimarchi | D6: ='Elenco Giocatori'!D562 -> A | E6: ='Elenco Giocatori'!E562 -> T | F6: ='Elenco Giocatori'!F562 -> Ravenna | G6: ='Elenco Giocatori'!AC562 -> 7.85 | H6: ='Elenco Giocatori'!H562 -> 7.65 | I6: ='Elenco Giocatori'!I562 -> 8.05 | J6: ='Elenco Giocatori'!J562 -> 6.9 | K6: ='Elenco Giocatori'!K562 -> 9.05 | L6: ='Elenco Giocatori'!L562 -> 8.7 | M6: ='Elenco Giocatori'!M562 -> 9.2 | N6: ='Elenco Giocatori'!N562 -> 7.15 | O6: ='Elenco Giocatori'!O562 -> 6.5 | ... Z6: ='Elenco Giocatori'!Z562
B7: {=_xlfn.XLOOKUP(C7,Disponibili!G:G,Disponibili!F:F)} -> 32 | C7: ='Elenco Giocatori'!C39 -> Antonio Cirino | D7: ='Elenco Giocatori'!D39 -> B | E7: ='Elenco Giocatori'!E39 -> T | F7: ='Elenco Giocatori'!F39 -> Alessandria | G7: ='Elenco Giocatori'!AC39 -> 6.2 | H7: ='Elenco Giocatori'!H39 -> 6.2 | I7: ='Elenco Giocatori'!I39 | J7: ='Elenco Giocatori'!J39 | K7: ='Elenco Giocatori'!K39 | L7: ='Elenco Giocatori'!L39 | M7: ='Elenco Giocatori'!M39 | N7: ='Elenco Giocatori'!N39 | O7: ='Elenco Giocatori'!O39 | ... Z7: ='Elenco Giocatori'!Z39
B8: {=_xlfn.XLOOKUP(C8,Disponibili!G:G,Disponibili!F:F)} -> 37 | C8: ='Elenco Giocatori'!C44 -> Samuele D'Angelo | D8: ='Elenco Giocatori'!D44 -> B | E8: ='Elenco Giocatori'!E44 -> W | F8: ='Elenco Giocatori'!F44 -> Alessandria | G8: ='Elenco Giocatori'!AC44 -> 6.7 | H8: ='Elenco Giocatori'!H44 | I8: ='Elenco Giocatori'!I44 -> 6.7 | J8: ='Elenco Giocatori'!J44 | K8: ='Elenco Giocatori'!K44 | L8: ='Elenco Giocatori'!L44 | M8: ='Elenco Giocatori'!M44 | N8: ='Elenco Giocatori'!N44 | O8: ='Elenco Giocatori'!O44 | ... Z8: ='Elenco Giocatori'!Z44
B9: {=_xlfn.XLOOKUP(C9,Disponibili!G:G,Disponibili!F:F)} -> 240 | C9: ='Elenco Giocatori'!C40 -> Mariano Pizzuti | D9: ='Elenco Giocatori'!D40 -> A | E9: ='Elenco Giocatori'!E40 -> A | F9: ='Elenco Giocatori'!F40 -> Cremonese | G9: ='Elenco Giocatori'!AC40 -> 7.2104167 | H9: ='Elenco Giocatori'!H40 -> 6.15 | I9: ='Elenco Giocatori'!I40 -> 6.65 | J9: ='Elenco Giocatori'!J40 -> 7.25 | K9: ='Elenco Giocatori'!K40 -> 7.95 | L9: ='Elenco Giocatori'!L40 -> 7.3333333 | M9: ='Elenco Giocatori'!M40 -> 7.6 | N9: ='Elenco Giocatori'!N40 -> 6.9 | O9: ='Elenco Giocatori'!O40 | ... Z9: ='Elenco Giocatori'!Z40
B10: {=_xlfn.XLOOKUP(C10,Disponibili!G:G,Disponibili!F:F)} -> 49 | C10: ='Elenco Giocatori'!C56 -> Pasquale D'Abbraccio | D10: ='Elenco Giocatori'!D56 -> A | E10: ='Elenco Giocatori'!E56 -> C | F10: ='Elenco Giocatori'!F56 -> Avellino | G10: ='Elenco Giocatori'!AC56 -> 7.725 | H10: ='Elenco Giocatori'!H56 | I10: ='Elenco Giocatori'!I56 | J10: ='Elenco Giocatori'!J56 | K10: ='Elenco Giocatori'!K56 | L10: ='Elenco Giocatori'!L56 -> 8 | M10: ='Elenco Giocatori'!M56 | N10: ='Elenco Giocatori'!N56 -> 7.45 | O10: ='Elenco Giocatori'!O56 | ... Z10: ='Elenco Giocatori'!Z56
B11: {=_xlfn.XLOOKUP(C11,Disponibili!G:G,Disponibili!F:F)} -> 48 | C11: ='Elenco Giocatori'!C55 -> Lorenzo Donati | D11: ='Elenco Giocatori'!D55 -> A | E11: ='Elenco Giocatori'!E55 -> C | F11: ='Elenco Giocatori'!F55 -> Avellino | G11: ='Elenco Giocatori'!AC55 -> 6.1 | H11: ='Elenco Giocatori'!H55 -> 6.1 | I11: ='Elenco Giocatori'!I55 | J11: ='Elenco Giocatori'!J55 | K11: ='Elenco Giocatori'!K55 | L11: ='Elenco Giocatori'!L55 | M11: ='Elenco Giocatori'!M55 | N11: ='Elenco Giocatori'!N55 | O11: ='Elenco Giocatori'!O55 | ... Z11: ='Elenco Giocatori'!Z55
B12: {=_xlfn.XLOOKUP(C12,Disponibili!G:G,Disponibili!F:F)} -> 197 | C12: ='Elenco Giocatori'!C375 -> Stefano Pellone | D12: ='Elenco Giocatori'!D375 -> B | E12: ='Elenco Giocatori'!E375 -> D | F12: ='Elenco Giocatori'!F375 -> Catanzaro | G12: ='Elenco Giocatori'!AC375 -> 6.8433333 | H12: ='Elenco Giocatori'!H375 -> 7.35 | I12: ='Elenco Giocatori'!I375 -> 6.85 | J12: ='Elenco Giocatori'!J375 -> 7.225 | K12: ='Elenco Giocatori'!K375 -> 6.475 | L12: ='Elenco Giocatori'!L375 -> 6.8833333 | M12: ='Elenco Giocatori'!M375 -> 6.7 | N12: ='Elenco Giocatori'!N375 -> 5.9 | O12: ='Elenco Giocatori'!O375 -> 6.725 | ... Z12: ='Elenco Giocatori'!Z375
B13: {=_xlfn.XLOOKUP(C13,Disponibili!G:G,Disponibili!F:F)} -> 51 | C13: ='Elenco Giocatori'!C58 -> Davide Sigillò | D13: ='Elenco Giocatori'!D58 -> A | E13: ='Elenco Giocatori'!E58 -> D | F13: ='Elenco Giocatori'!F58 -> Avellino | G13: ='Elenco Giocatori'!AC58 -> 6.2875 | H13: ='Elenco Giocatori'!H58 | I13: ='Elenco Giocatori'!I58 -> 6.475 | J13: ='Elenco Giocatori'!J58 -> 6.1 | K13: ='Elenco Giocatori'!K58 | L13: ='Elenco Giocatori'!L58 | M13: ='Elenco Giocatori'!M58 | N13: ='Elenco Giocatori'!N58 | O13: ='Elenco Giocatori'!O58 | ... Z13: ='Elenco Giocatori'!Z58
B14: {=_xlfn.XLOOKUP(C14,Disponibili!G:G,Disponibili!F:F)} -> 55 | C14: ='Elenco Giocatori'!C62 -> Marco Zanaboni | D14: ='Elenco Giocatori'!D62 -> A | E14: ='Elenco Giocatori'!E62 -> P | F14: ='Elenco Giocatori'!F62 -> Avellino | G14: ='Elenco Giocatori'!AC62 -> 6.8 | H14: ='Elenco Giocatori'!H62 | I14: ='Elenco Giocatori'!I62 -> 6.8 | J14: ='Elenco Giocatori'!J62 | K14: ='Elenco Giocatori'!K62 | L14: ='Elenco Giocatori'!L62 | M14: ='Elenco Giocatori'!M62 | N14: ='Elenco Giocatori'!N62 | O14: ='Elenco Giocatori'!O62 | ... Z14: ='Elenco Giocatori'!Z62
B15: {=_xlfn.XLOOKUP(C15,Disponibili!G:G,Disponibili!F:F)} -> 377 | C15: ='Elenco Giocatori'!C63 -> Alberto Locatelli | D15: ='Elenco Giocatori'!D63 -> A | E15: ='Elenco Giocatori'!E63 -> A | F15: ='Elenco Giocatori'!F63 -> Inter | G15: ='Elenco Giocatori'!AC63 -> 7.3888889 | H15: ='Elenco Giocatori'!H63 -> 10.05 | I15: ='Elenco Giocatori'!I63 -> 6.25 | J15: ='Elenco Giocatori'!J63 -> 9.75 | K15: ='Elenco Giocatori'!K63 -> 6.25 | L15: ='Elenco Giocatori'!L63 -> 6.5 | M15: ='Elenco Giocatori'!M63 -> 7.8 | N15: ='Elenco Giocatori'!N63 -> 6.3 | O15: ='Elenco Giocatori'!O63 -> 6.1 | ... Z15: ='Elenco Giocatori'!Z63
B16: {=_xlfn.XLOOKUP(C16,Disponibili!G:G,Disponibili!F:F)} -> 63 | C16: ='Elenco Giocatori'!C70 -> Samuele Tomassetti | D16: ='Elenco Giocatori'!D70 -> A | E16: ='Elenco Giocatori'!E70 -> A | F16: ='Elenco Giocatori'!F70 -> Bari | G16: ='Elenco Giocatori'!AC70 -> 7.4 | H16: ='Elenco Giocatori'!H70 -> 7.4 | I16: ='Elenco Giocatori'!I70 | J16: ='Elenco Giocatori'!J70 | K16: ='Elenco Giocatori'!K70 | L16: ='Elenco Giocatori'!L70 | M16: ='Elenco Giocatori'!M70 | N16: ='Elenco Giocatori'!N70 | O16: ='Elenco Giocatori'!O70 | ... Z16: ='Elenco Giocatori'!Z70
B17: {=_xlfn.XLOOKUP(C17,Disponibili!G:G,Disponibili!F:F)} -> 42 | C17: ='Elenco Giocatori'!C71 -> Raoul Guzzi | D17: ='Elenco Giocatori'!D71 -> A | E17: ='Elenco Giocatori'!E71 -> A | F17: ='Elenco Giocatori'!F71 -> Avellino | G17: ='Elenco Giocatori'!AC71 -> 7.6166667 | H17: ='Elenco Giocatori'!H71 | I17: ='Elenco Giocatori'!I71 | J17: ='Elenco Giocatori'!J71 | K17: ='Elenco Giocatori'!K71 | L17: ='Elenco Giocatori'!L71 | M17: ='Elenco Giocatori'!M71 | N17: ='Elenco Giocatori'!N71 | O17: ='Elenco Giocatori'!O71 -> 8.4 | ... Z17: ='Elenco Giocatori'!Z71
B18: {=_xlfn.XLOOKUP(C18,Disponibili!G:G,Disponibili!F:F)} -> 527 | C18: ='Elenco Giocatori'!C467 -> Alfredo Aloi | D18: ='Elenco Giocatori'!D467 -> B | E18: ='Elenco Giocatori'!E467 -> P | F18: ='Elenco Giocatori'!F467 -> Novara | G18: ='Elenco Giocatori'!AC467 -> 6.85 | H18: ='Elenco Giocatori'!H467 | I18: ='Elenco Giocatori'!I467 -> 6.3 | J18: ='Elenco Giocatori'!J467 | K18: ='Elenco Giocatori'!K467 | L18: ='Elenco Giocatori'!L467 | M18: ='Elenco Giocatori'!M467 | N18: ='Elenco Giocatori'!N467 | O18: ='Elenco Giocatori'!O467 | ... Z18: ='Elenco Giocatori'!Z467
B19: {=_xlfn.XLOOKUP(C19,Disponibili!G:G,Disponibili!F:F)} -> 78 | C19: ='Elenco Giocatori'!C85 -> Alessandro Gallo | D19: ='Elenco Giocatori'!D85 -> A | E19: ='Elenco Giocatori'!E85 -> A | F19: ='Elenco Giocatori'!F85 -> Bologna | G19: ='Elenco Giocatori'!AC85 -> 7.05 | H19: ='Elenco Giocatori'!H85 -> 6.85 | I19: ='Elenco Giocatori'!I85 | J19: ='Elenco Giocatori'!J85 | K19: ='Elenco Giocatori'!K85 -> 7.25 | L19: ='Elenco Giocatori'!L85 | M19: ='Elenco Giocatori'!M85 | N19: ='Elenco Giocatori'!N85 | O19: ='Elenco Giocatori'!O85 | ... Z19: ='Elenco Giocatori'!Z85
B20: {=_xlfn.XLOOKUP(C20,Disponibili!G:G,Disponibili!F:F)} -> 82 | C20: ='Elenco Giocatori'!C89 -> Antonio Di Gloria | D20: ='Elenco Giocatori'!D89 -> A | E20: ='Elenco Giocatori'!E89 -> C | F20: ='Elenco Giocatori'!F89 -> Bologna | G20: ='Elenco Giocatori'!AC89 -> 7.21 | H20: ='Elenco Giocatori'!H89 -> 6.9 | I20: ='Elenco Giocatori'!I89 -> 6.85 | J20: ='Elenco Giocatori'!J89 -> 8.1 | K20: ='Elenco Giocatori'!K89 -> 6.55 | L20: ='Elenco Giocatori'!L89 | M20: ='Elenco Giocatori'!M89 | N20: ='Elenco Giocatori'!N89 -> 7.65 | O20: ='Elenco Giocatori'!O89 | ... Z20: ='Elenco Giocatori'!Z89
B21: {=_xlfn.XLOOKUP(C21,Disponibili!G:G,Disponibili!F:F)} -> 85 | C21: ='Elenco Giocatori'!C92 -> Matteo Fratti | D21: ='Elenco Giocatori'!D92 -> A | E21: ='Elenco Giocatori'!E92 -> D | F21: ='Elenco Giocatori'!F92 -> Bologna | G21: ='Elenco Giocatori'!AC92 -> 6.5 | H21: ='Elenco Giocatori'!H92 -> 6.5 | I21: ='Elenco Giocatori'!I92 | J21: ='Elenco Giocatori'!J92 | K21: ='Elenco Giocatori'!K92 | L21: ='Elenco Giocatori'!L92 | M21: ='Elenco Giocatori'!M92 | N21: ='Elenco Giocatori'!N92 | O21: ='Elenco Giocatori'!O92 | ... Z21: ='Elenco Giocatori'!Z92
B22: {=_xlfn.XLOOKUP(C22,Disponibili!G:G,Disponibili!F:F)} -> 86 | C22: ='Elenco Giocatori'!C93 -> Mauro Catalano | D22: ='Elenco Giocatori'!D93 -> A | E22: ='Elenco Giocatori'!E93 -> D | F22: ='Elenco Giocatori'!F93 -> Bologna | G22: ='Elenco Giocatori'!AC93 -> 6.3416667 | H22: ='Elenco Giocatori'!H93 | I22: ='Elenco Giocatori'!I93 | J22: ='Elenco Giocatori'!J93 -> 6.15 | K22: ='Elenco Giocatori'!K93 | L22: ='Elenco Giocatori'!L93 -> 6.5333333 | M22: ='Elenco Giocatori'!M93 | N22: ='Elenco Giocatori'!N93 | O22: ='Elenco Giocatori'!O93 | ... Z22: ='Elenco Giocatori'!Z93
B23: {=_xlfn.XLOOKUP(C23,Disponibili!G:G,Disponibili!F:F)} -> 88 | C23: ='Elenco Giocatori'!C95 -> Loris Tigli | D23: ='Elenco Giocatori'!D95 -> A | E23: ='Elenco Giocatori'!E95 -> P | F23: ='Elenco Giocatori'!F95 -> Bologna | G23: ='Elenco Giocatori'!AC95 -> 5.4 | H23: ='Elenco Giocatori'!H95 -> 5.4 | I23: ='Elenco Giocatori'!I95 | J23: ='Elenco Giocatori'!J95 | K23: ='Elenco Giocatori'!K95 | L23: ='Elenco Giocatori'!L95 | M23: ='Elenco Giocatori'!M95 | N23: ='Elenco Giocatori'!N95 | O23: ='Elenco Giocatori'!O95 | ... Z23: ='Elenco Giocatori'!Z95
B24: {=_xlfn.XLOOKUP(C24,Disponibili!G:G,Disponibili!F:F)} -> 321 | C24: ='Elenco Giocatori'!C577 -> Davyd Andriyesh | D24: ='Elenco Giocatori'!D577 -> A | E24: ='Elenco Giocatori'!E577 -> C | F24: ='Elenco Giocatori'!F577 -> Forst Sudtirol | G24: ='Elenco Giocatori'!AC577 -> 6.075 | H24: ='Elenco Giocatori'!H577 | I24: ='Elenco Giocatori'!I577 | J24: ='Elenco Giocatori'!J577 | K24: ='Elenco Giocatori'!K577 | L24: ='Elenco Giocatori'!L577 | M24: ='Elenco Giocatori'!M577 | N24: ='Elenco Giocatori'!N577 | O24: ='Elenco Giocatori'!O577 -> 5.9 | ... Z24: ='Elenco Giocatori'!Z577
B25: {=_xlfn.XLOOKUP(C25,Disponibili!G:G,Disponibili!F:F)} -> 96 | C25: ='Elenco Giocatori'!C103 -> Stefano Cotta | D25: ='Elenco Giocatori'!D103 -> A | E25: ='Elenco Giocatori'!E103 -> W | F25: ='Elenco Giocatori'!F103 -> Bologna | G25: ='Elenco Giocatori'!AC103 -> 6.5 | H25: ='Elenco Giocatori'!H103 -> 6.5 | I25: ='Elenco Giocatori'!I103 | J25: ='Elenco Giocatori'!J103 | K25: ='Elenco Giocatori'!K103 | L25: ='Elenco Giocatori'!L103 | M25: ='Elenco Giocatori'!M103 | N25: ='Elenco Giocatori'!N103 | O25: ='Elenco Giocatori'!O103 | ... Z25: ='Elenco Giocatori'!Z103
B26: {=_xlfn.XLOOKUP(C26,Disponibili!G:G,Disponibili!F:F)} -> 95 | C26: ='Elenco Giocatori'!C102 -> Angela Iadicicco | D26: ='Elenco Giocatori'!D102 -> A | E26: ='Elenco Giocatori'!E102 -> W | F26: ='Elenco Giocatori'!F102 -> Bologna | G26: ='Elenco Giocatori'!AC102 -> 5.5 | H26: ='Elenco Giocatori'!H102 | I26: ='Elenco Giocatori'!I102 -> 5.5 | J26: ='Elenco Giocatori'!J102 | K26: ='Elenco Giocatori'!K102 | L26: ='Elenco Giocatori'!L102 | M26: ='Elenco Giocatori'!M102 | N26: ='Elenco Giocatori'!N102 | O26: ='Elenco Giocatori'!O102 | ... Z26: ='Elenco Giocatori'!Z102
B27: {=_xlfn.XLOOKUP(C27,Disponibili!G:G,Disponibili!F:F)} -> 101 | C27: ='Elenco Giocatori'!C108 -> Camillo Ferrigni | D27: ='Elenco Giocatori'!D108 -> B | E27: ='Elenco Giocatori'!E108 -> D | F27: ='Elenco Giocatori'!F108 -> Brescia | G27: ='Elenco Giocatori'!AC108 -> 6.9 | H27: ='Elenco Giocatori'!H108 | I27: ='Elenco Giocatori'!I108 | J27: ='Elenco Giocatori'!J108 -> 6.9 | K27: ='Elenco Giocatori'!K108 | L27: ='Elenco Giocatori'!L108 | M27: ='Elenco Giocatori'!M108 | N27: ='Elenco Giocatori'!N108 | O27: ='Elenco Giocatori'!O108 | ... Z27: ='Elenco Giocatori'!Z108
B28: {=_xlfn.XLOOKUP(C28,Disponibili!G:G,Disponibili!F:F)} -> 103 | C28: ='Elenco Giocatori'!C110 -> Riccardo Rex | D28: ='Elenco Giocatori'!D110 -> B | E28: ='Elenco Giocatori'!E110 -> D | F28: ='Elenco Giocatori'!F110 -> Brescia | G28: ='Elenco Giocatori'!AC110 -> 6.35 | H28: ='Elenco Giocatori'!H110 | I28: ='Elenco Giocatori'!I110 | J28: ='Elenco Giocatori'!J110 -> 6.35 | K28: ='Elenco Giocatori'!K110 | L28: ='Elenco Giocatori'!L110 | M28: ='Elenco Giocatori'!M110 | N28: ='Elenco Giocatori'!N110 | O28: ='Elenco Giocatori'!O110 | ... Z28: ='Elenco Giocatori'!Z110
B29: {=_xlfn.XLOOKUP(C29,Disponibili!G:G,Disponibili!F:F)} -> 112 | C29: ='Elenco Giocatori'!C119 -> Walter Genna | D29: ='Elenco Giocatori'!D119 -> B | E29: ='Elenco Giocatori'!E119 -> W | F29: ='Elenco Giocatori'!F119 -> Brescia | G29: ='Elenco Giocatori'!AC119 -> 6 | H29: ='Elenco Giocatori'!H119 -> 6 | I29: ='Elenco Giocatori'!I119 | J29: ='Elenco Giocatori'!J119 | K29: ='Elenco Giocatori'!K119 | L29: ='Elenco Giocatori'!L119 | M29: ='Elenco Giocatori'!M119 | N29: ='Elenco Giocatori'!N119 | O29: ='Elenco Giocatori'!O119 | ... Z29: ='Elenco Giocatori'!Z119
B30: {=_xlfn.XLOOKUP(C30,Disponibili!G:G,Disponibili!F:F)} -> 123 | C30: ='Elenco Giocatori'!C130 -> Gian Franco Sanna | D30: ='Elenco Giocatori'!D130 -> B | E30: ='Elenco Giocatori'!E130 -> T | F30: ='Elenco Giocatori'!F130 -> Cagliari | G30: ='Elenco Giocatori'!AC130 -> 6 | H30: ='Elenco Giocatori'!H130 | I30: ='Elenco Giocatori'!I130 -> 6 | J30: ='Elenco Giocatori'!J130 | K30: ='Elenco Giocatori'!K130 | L30: ='Elenco Giocatori'!L130 | M30: ='Elenco Giocatori'!M130 | N30: ='Elenco Giocatori'!N130 | O30: ='Elenco Giocatori'!O130 | ... Z30: ='Elenco Giocatori'!Z130
B31: {=_xlfn.XLOOKUP(C31,Disponibili!G:G,Disponibili!F:F)} -> 1 | C31: ='Elenco Giocatori'!C8 -> Antonio Vittorio Montuori | D31: ='Elenco Giocatori'!D8 -> B | E31: ='Elenco Giocatori'!E8 -> A | F31: ='Elenco Giocatori'!F8 -> Akragas | G31: ='Elenco Giocatori'!AC8 -> 0 | H31: ='Elenco Giocatori'!H8 | I31: ='Elenco Giocatori'!I8 | J31: ='Elenco Giocatori'!J8 | K31: ='Elenco Giocatori'!K8 | L31: ='Elenco Giocatori'!L8 | M31: ='Elenco Giocatori'!M8 | N31: ='Elenco Giocatori'!N8 | O31: ='Elenco Giocatori'!O8 | ... Z31: ='Elenco Giocatori'!Z8
B32: {=_xlfn.XLOOKUP(C32,Disponibili!G:G,Disponibili!F:F)} -> 18 | C32: ='Elenco Giocatori'!C25 -> Simone Lucatelli | D32: ='Elenco Giocatori'!D25 -> B | E32: ='Elenco Giocatori'!E25 -> A | F32: ='Elenco Giocatori'!F25 -> Akragas | G32: ='Elenco Giocatori'!AC25 -> 0 | H32: ='Elenco Giocatori'!H25 | I32: ='Elenco Giocatori'!I25 | J32: ='Elenco Giocatori'!J25 | K32: ='Elenco Giocatori'!K25 | L32: ='Elenco Giocatori'!L25 | M32: ='Elenco Giocatori'!M25 | N32: ='Elenco Giocatori'!N25 | O32: ='Elenco Giocatori'!O25 | ... Z32: ='Elenco Giocatori'!Z25
B33: {=_xlfn.XLOOKUP(C33,Disponibili!G:G,Disponibili!F:F)} -> 21 | C33: ='Elenco Giocatori'!C28 -> Alex Ferrari | D33: ='Elenco Giocatori'!D28 -> B | E33: ='Elenco Giocatori'!E28 -> A | F33: ='Elenco Giocatori'!F28 -> Alessandria | G33: ='Elenco Giocatori'!AC28 -> 0 | H33: ='Elenco Giocatori'!H28 | I33: ='Elenco Giocatori'!I28 | J33: ='Elenco Giocatori'!J28 | K33: ='Elenco Giocatori'!K28 | L33: ='Elenco Giocatori'!L28 | M33: ='Elenco Giocatori'!M28 | N33: ='Elenco Giocatori'!N28 | O33: ='Elenco Giocatori'!O28 | ... Z33: ='Elenco Giocatori'!Z28
B34: {=_xlfn.XLOOKUP(C34,Disponibili!G:G,Disponibili!F:F)} -> 22 | C34: ='Elenco Giocatori'!C29 -> Giacomo Varotto | D34: ='Elenco Giocatori'!D29 -> B | E34: ='Elenco Giocatori'!E29 -> A | F34: ='Elenco Giocatori'!F29 -> Alessandria | G34: ='Elenco Giocatori'!AC29 -> 0 | H34: ='Elenco Giocatori'!H29 | I34: ='Elenco Giocatori'!I29 | J34: ='Elenco Giocatori'!J29 | K34: ='Elenco Giocatori'!K29 | L34: ='Elenco Giocatori'!L29 | M34: ='Elenco Giocatori'!M29 | N34: ='Elenco Giocatori'!N29 | O34: ='Elenco Giocatori'!O29 | ... Z34: ='Elenco Giocatori'!Z29
B35: {=_xlfn.XLOOKUP(C35,Disponibili!G:G,Disponibili!F:F)} -> 23 | C35: ='Elenco Giocatori'!C30 -> Lorenzo Foggi Viligiardi | D35: ='Elenco Giocatori'!D30 -> B | E35: ='Elenco Giocatori'!E30 -> A | F35: ='Elenco Giocatori'!F30 -> Alessandria | G35: ='Elenco Giocatori'!AC30 -> 0 | H35: ='Elenco Giocatori'!H30 | I35: ='Elenco Giocatori'!I30 | J35: ='Elenco Giocatori'!J30 | K35: ='Elenco Giocatori'!K30 | L35: ='Elenco Giocatori'!L30 | M35: ='Elenco Giocatori'!M30 | N35: ='Elenco Giocatori'!N30 | O35: ='Elenco Giocatori'!O30 | ... Z35: ='Elenco Giocatori'!Z30
B36: {=_xlfn.XLOOKUP(C36,Disponibili!G:G,Disponibili!F:F)} -> 39 | C36: ='Elenco Giocatori'!C46 -> Aipom Manhattan | D36: ='Elenco Giocatori'!D46 -> A | E36: ='Elenco Giocatori'!E46 -> A | F36: ='Elenco Giocatori'!F46 -> Avellino | G36: ='Elenco Giocatori'!AC46 -> 0 | H36: ='Elenco Giocatori'!H46 | I36: ='Elenco Giocatori'!I46 | J36: ='Elenco Giocatori'!J46 | K36: ='Elenco Giocatori'!K46 | L36: ='Elenco Giocatori'!L46 | M36: ='Elenco Giocatori'!M46 | N36: ='Elenco Giocatori'!N46 | O36: ='Elenco Giocatori'!O46 | ... Z36: ='Elenco Giocatori'!Z46
B37: {=_xlfn.XLOOKUP(C37,Disponibili!G:G,Disponibili!F:F)} -> 40 | C37: ='Elenco Giocatori'!C47 -> Alessio Gega | D37: ='Elenco Giocatori'!D47 -> A | E37: ='Elenco Giocatori'!E47 -> A | F37: ='Elenco Giocatori'!F47 -> Avellino | G37: ='Elenco Giocatori'!AC47 -> 0 | H37: ='Elenco Giocatori'!H47 | I37: ='Elenco Giocatori'!I47 | J37: ='Elenco Giocatori'!J47 | K37: ='Elenco Giocatori'!K47 | L37: ='Elenco Giocatori'!L47 | M37: ='Elenco Giocatori'!M47 | N37: ='Elenco Giocatori'!N47 | O37: ='Elenco Giocatori'!O47 | ... Z37: ='Elenco Giocatori'!Z47
B38: {=_xlfn.XLOOKUP(C38,Disponibili!G:G,Disponibili!F:F)} -> 41 | C38: ='Elenco Giocatori'!C48 -> Antonio Ippolito | D38: ='Elenco Giocatori'!D48 -> A | E38: ='Elenco Giocatori'!E48 -> A | F38: ='Elenco Giocatori'!F48 -> Avellino | G38: ='Elenco Giocatori'!AC48 -> 0 | H38: ='Elenco Giocatori'!H48 | I38: ='Elenco Giocatori'!I48 | J38: ='Elenco Giocatori'!J48 | K38: ='Elenco Giocatori'!K48 | L38: ='Elenco Giocatori'!L48 | M38: ='Elenco Giocatori'!M48 | N38: ='Elenco Giocatori'!N48 | O38: ='Elenco Giocatori'!O48 | ... Z38: ='Elenco Giocatori'!Z48
B39: {=_xlfn.XLOOKUP(C39,Disponibili!G:G,Disponibili!F:F)} -> 60 | C39: ='Elenco Giocatori'!C67 -> Francesco Bomber Squeo | D39: ='Elenco Giocatori'!D67 -> A | E39: ='Elenco Giocatori'!E67 -> A | F39: ='Elenco Giocatori'!F67 -> Bari | G39: ='Elenco Giocatori'!AC67 -> 0 | H39: ='Elenco Giocatori'!H67 | I39: ='Elenco Giocatori'!I67 | J39: ='Elenco Giocatori'!J67 | K39: ='Elenco Giocatori'!K67 | L39: ='Elenco Giocatori'!L67 | M39: ='Elenco Giocatori'!M67 | N39: ='Elenco Giocatori'!N67 | O39: ='Elenco Giocatori'!O67 | ... Z39: ='Elenco Giocatori'!Z67
B40: {=_xlfn.XLOOKUP(C40,Disponibili!G:G,Disponibili!F:F)} -> 61 | C40: ='Elenco Giocatori'!C68 -> Daniele Alluviani | D40: ='Elenco Giocatori'!D68 -> A | E40: ='Elenco Giocatori'!E68 -> A | F40: ='Elenco Giocatori'!F68 -> Bari | G40: ='Elenco Giocatori'!AC68 -> 0 | H40: ='Elenco Giocatori'!H68 | I40: ='Elenco Giocatori'!I68 | J40: ='Elenco Giocatori'!J68 | K40: ='Elenco Giocatori'!K68 | L40: ='Elenco Giocatori'!L68 | M40: ='Elenco Giocatori'!M68 | N40: ='Elenco Giocatori'!N68 | O40: ='Elenco Giocatori'!O68 | ... Z40: ='Elenco Giocatori'!Z68
B41: {=_xlfn.XLOOKUP(C41,Disponibili!G:G,Disponibili!F:F)} -> 62 | C41: ='Elenco Giocatori'!C69 -> Mirko Ambrosi | D41: ='Elenco Giocatori'!D69 -> A | E41: ='Elenco Giocatori'!E69 -> A | F41: ='Elenco Giocatori'!F69 -> Bari | G41: ='Elenco Giocatori'!AC69 -> 0 | H41: ='Elenco Giocatori'!H69 | I41: ='Elenco Giocatori'!I69 | J41: ='Elenco Giocatori'!J69 | K41: ='Elenco Giocatori'!K69 | L41: ='Elenco Giocatori'!L69 | M41: ='Elenco Giocatori'!M69 | N41: ='Elenco Giocatori'!N69 | O41: ='Elenco Giocatori'!O69 | ... Z41: ='Elenco Giocatori'!Z69
...

Sheet Premi
B2: Guadagni Totali | E2: Concorsi Settimanali | H2: Classifica Finale | K2: Bonus Fedeltà
B3: Utente | C3: Crediti | E3: Utente | F3: Crediti | H3: Utente | I3: Crediti | K3: Utente | L3: Crediti
B4: =IFERROR(__xludf.DUMMYFUNCTION("(QUERY('Classifiche e premi'!$Q$2:$R1000, ""select Col1, Col2 where Col2 >0 Order by Col2 Desc""))"),"Nicola Madeddu") -> Nicola Madeddu | C4: =IFERROR(__xludf.DUMMYFUNCTION("""COMPUTED_VALUE"""),300000.0) -> 300000 | E4: =IFERROR(__xludf.DUMMYFUNCTION("(QUERY('Classifiche e premi'!H2:I1000, ""select Col1, Col2 where Col2 >0 and Col1<> '#REF!' Order by Col2 Desc""))"),"Gaetano Baiamonte") -> Gaetano Baiamonte | F4: =IFERROR(__xludf.DUMMYFUNCTION("""COMPUTED_VALUE"""),55000.0) -> 55000 | H4: =IFERROR(__xludf.DUMMYFUNCTION("(QUERY('Classifica generale'!D4:D11, ""select Col1""))"),"Nicola Madeddu") -> Nicola Madeddu | I4: 200000 | K4: =IFERROR(__xludf.DUMMYFUNCTION("(QUERY('Bonus Fedeltà'!$E$4:$H1000, ""select Col1, Col4""))"),"Alessandro Gallo") -> Alessandro Gallo | L4: =IFERROR(__xludf.DUMMYFUNCTION("""COMPUTED_VALUE"""),50000.0) -> 50000
B5: =IFERROR(__xludf.DUMMYFUNCTION("""COMPUTED_VALUE"""),"Gaetano Baiamonte") -> Gaetano Baiamonte | C5: =IFERROR(__xludf.DUMMYFUNCTION("""COMPUTED_VALUE"""),255000.0) -> 255000 | E5: =IFERROR(__xludf.DUMMYFUNCTION("""COMPUTED_VALUE"""),"Nicola Madeddu") -> Nicola Madeddu | F5: =IFERROR(__xludf.DUMMYFUNCTION("""COMPUTED_VALUE"""),50000.0) -> 50000 | H5: =IFERROR(__xludf.DUMMYFUNCTION("""COMPUTED_VALUE"""),"Gaetano Baiamonte") -> Gaetano Baiamonte | I5: 150000 | K5: =IFERROR(__xludf.DUMMYFUNCTION("""COMPUTED_VALUE"""),"Alessio Chiarelli") -> Alessio Chiarelli | L5: =IFERROR(__xludf.DUMMYFUNCTION("""COMPUTED_VALUE"""),50000.0) -> 50000
B6: =IFERROR(__xludf.DUMMYFUNCTION("""COMPUTED_VALUE"""),"Gianfranco Colucci") -> Gianfranco Colucci | C6: =IFERROR(__xludf.DUMMYFUNCTION("""COMPUTED_VALUE"""),170000.0) -> 170000 | E6: =IFERROR(__xludf.DUMMYFUNCTION("""COMPUTED_VALUE"""),"Paola Alessandra Pisani") -> Paola Alessandra Pisani | F6: =IFERROR(__xludf.DUMMYFUNCTION("""COMPUTED_VALUE"""),30000.0) -> 30000 | H6: =IFERROR(__xludf.DUMMYFUNCTION("""COMPUTED_VALUE"""),"Gianfranco Colucci") -> Gianfranco Colucci | I6: 100000 | L6: =IFERROR(__xludf.DUMMYFUNCTION("""COMPUTED_VALUE"""),50000.0) -> 50000
B7: =IFERROR(__xludf.DUMMYFUNCTION("""COMPUTED_VALUE"""),"Luca Pedroletti") -> Luca Pedroletti | C7: =IFERROR(__xludf.DUMMYFUNCTION("""COMPUTED_VALUE"""),145000.0) -> 145000 | E7: =IFERROR(__xludf.DUMMYFUNCTION("""COMPUTED_VALUE"""),"Raffaele Zicolella") -> Raffaele Zicolella | F7: =IFERROR(__xludf.DUMMYFUNCTION("""COMPUTED_VALUE"""),25000.0) -> 25000 | H7: =IFERROR(__xludf.DUMMYFUNCTION("""COMPUTED_VALUE"""),"Luca Pedroletti") -> Luca Pedroletti | I7: 70000 | K7: =IFERROR(__xludf.DUMMYFUNCTION("""COMPUTED_VALUE"""),"Angela Iadicicco") -> Angela Iadicicco | L7: =IFERROR(__xludf.DUMMYFUNCTION("""COMPUTED_VALUE"""),50000.0) -> 50000
B8: =IFERROR(__xludf.DUMMYFUNCTION("""COMPUTED_VALUE"""),"Paola Alessandra Pisani") -> Paola Alessandra Pisani | C8: =IFERROR(__xludf.DUMMYFUNCTION("""COMPUTED_VALUE"""),110000.0) -> 110000 | E8: =IFERROR(__xludf.DUMMYFUNCTION("""COMPUTED_VALUE"""),"Luca Pedroletti") -> Luca Pedroletti | F8: =IFERROR(__xludf.DUMMYFUNCTION("""COMPUTED_VALUE"""),25000.0) -> 25000 | H8: =IFERROR(__xludf.DUMMYFUNCTION("""COMPUTED_VALUE"""),"Tizio Caio") -> Tizio Caio | I8: 60000 | K8: =IFERROR(__xludf.DUMMYFUNCTION("""COMPUTED_VALUE"""),"Antonio Cirino") -> Antonio Cirino | L8: =IFERROR(__xludf.DUMMYFUNCTION("""COMPUTED_VALUE"""),50000.0) -> 50000
B9: =IFERROR(__xludf.DUMMYFUNCTION("""COMPUTED_VALUE"""),"Francesco Fusco") -> Francesco Fusco | C9: =IFERROR(__xludf.DUMMYFUNCTION("""COMPUTED_VALUE"""),105000.0) -> 105000 | E9: =IFERROR(__xludf.DUMMYFUNCTION("""COMPUTED_VALUE"""),"Riccardo Ricci") -> Riccardo Ricci | F9: =IFERROR(__xludf.DUMMYFUNCTION("""COMPUTED_VALUE"""),20000.0) -> 20000 | H9: =IFERROR(__xludf.DUMMYFUNCTION("""COMPUTED_VALUE"""),"Loris Tigli") -> Loris Tigli | I9: 50000 | L9: =IFERROR(__xludf.DUMMYFUNCTION("""COMPUTED_VALUE"""),50000.0) -> 50000
B10: =IFERROR(__xludf.DUMMYFUNCTION("""COMPUTED_VALUE"""),"Loris Tigli") -> Loris Tigli | C10: =IFERROR(__xludf.DUMMYFUNCTION("""COMPUTED_VALUE"""),105000.0) -> 105000 | E10: =IFERROR(__xludf.DUMMYFUNCTION("""COMPUTED_VALUE"""),"Gianfranco Colucci") -> Gianfranco Colucci | F10: =IFERROR(__xludf.DUMMYFUNCTION("""COMPUTED_VALUE"""),20000.0) -> 20000 | H10: =IFERROR(__xludf.DUMMYFUNCTION("""COMPUTED_VALUE"""),"Francesco Fusco") -> Francesco Fusco | I10: 40000 | K10: =IFERROR(__xludf.DUMMYFUNCTION("""COMPUTED_VALUE"""),"Daniele Greca") -> Daniele Greca | L10: =IFERROR(__xludf.DUMMYFUNCTION("""COMPUTED_VALUE"""),50000.0) -> 50000
B11: =IFERROR(__xludf.DUMMYFUNCTION("""COMPUTED_VALUE"""),"Daniele Greca") -> Daniele Greca | C11: =IFERROR(__xludf.DUMMYFUNCTION("""COMPUTED_VALUE"""),70000.0) -> 70000 | E11: =IFERROR(__xludf.DUMMYFUNCTION("""COMPUTED_VALUE"""),"Alessandro Casiraro") -> Alessandro Casiraro | F11: =IFERROR(__xludf.DUMMYFUNCTION("""COMPUTED_VALUE"""),20000.0) -> 20000 | H11: =IFERROR(__xludf.DUMMYFUNCTION("""COMPUTED_VALUE"""),"Paola Alessandra Pisani") -> Paola Alessandra Pisani | I11: 30000 | L11: =IFERROR(__xludf.DUMMYFUNCTION("""COMPUTED_VALUE"""),50000.0) -> 50000
B12: =IFERROR(__xludf.DUMMYFUNCTION("""COMPUTED_VALUE"""),"Antonio Cirino") -> Antonio Cirino | C12: =IFERROR(__xludf.DUMMYFUNCTION("""COMPUTED_VALUE"""),65000.0) -> 65000 | E12: =IFERROR(__xludf.DUMMYFUNCTION("""COMPUTED_VALUE"""),"Daniele Greca") -> Daniele Greca | F12: =IFERROR(__xludf.DUMMYFUNCTION("""COMPUTED_VALUE"""),20000.0) -> 20000 | K12: =IFERROR(__xludf.DUMMYFUNCTION("""COMPUTED_VALUE"""),"Francesco Fusco") -> Francesco Fusco | L12: =IFERROR(__xludf.DUMMYFUNCTION("""COMPUTED_VALUE"""),50000.0) -> 50000
B13: =IFERROR(__xludf.DUMMYFUNCTION("""COMPUTED_VALUE"""),"Angela Iadicicco") -> Angela Iadicicco | C13: =IFERROR(__xludf.DUMMYFUNCTION("""COMPUTED_VALUE"""),55000.0) -> 55000 | E13: =IFERROR(__xludf.DUMMYFUNCTION("""COMPUTED_VALUE"""),"Francesco Fusco") -> Francesco Fusco | F13: =IFERROR(__xludf.DUMMYFUNCTION("""COMPUTED_VALUE"""),15000.0) -> 15000 | K13: =IFERROR(__xludf.DUMMYFUNCTION("""COMPUTED_VALUE"""),"Gaetano Baiamonte") -> Gaetano Baiamonte | L13: =IFERROR(__xludf.DUMMYFUNCTION("""COMPUTED_VALUE"""),50000.0) -> 50000
B14: =IFERROR(__xludf.DUMMYFUNCTION("""COMPUTED_VALUE"""),"Riccardo Todaro") -> Riccardo Todaro | C14: =IFERROR(__xludf.DUMMYFUNCTION("""COMPUTED_VALUE"""),55000.0) -> 55000 | E14: =IFERROR(__xludf.DUMMYFUNCTION("""COMPUTED_VALUE"""),"Antonio Cirino") -> Antonio Cirino | F14: =IFERROR(__xludf.DUMMYFUNCTION("""COMPUTED_VALUE"""),15000.0) -> 15000 | K14: =IFERROR(__xludf.DUMMYFUNCTION("""COMPUTED_VALUE"""),"Gianfranco Colucci") -> Gianfranco Colucci | L14: =IFERROR(__xludf.DUMMYFUNCTION("""COMPUTED_VALUE"""),50000.0) -> 50000
B15: =IFERROR(__xludf.DUMMYFUNCTION("""COMPUTED_VALUE"""),"Alessandro Gallo") -> Alessandro Gallo | C15: =IFERROR(__xludf.DUMMYFUNCTION("""COMPUTED_VALUE"""),50000.0) -> 50000 | E15: =IFERROR(__xludf.DUMMYFUNCTION("""COMPUTED_VALUE"""),"Stefano Serra") -> Stefano Serra | F15: =IFERROR(__xludf.DUMMYFUNCTION("""COMPUTED_VALUE"""),10000.0) -> 10000 | K15: =IFERROR(__xludf.DUMMYFUNCTION("""COMPUTED_VALUE"""),"Klaus Trophobico") -> Klaus Trophobico | L15: =IFERROR(__xludf.DUMMYFUNCTION("""COMPUTED_VALUE"""),50000.0) -> 50000
B16: =IFERROR(__xludf.DUMMYFUNCTION("""COMPUTED_VALUE"""),"Alessio Chiarelli") -> Alessio Chiarelli | C16: =IFERROR(__xludf.DUMMYFUNCTION("""COMPUTED_VALUE"""),50000.0) -> 50000 | E16: =IFERROR(__xludf.DUMMYFUNCTION("""COMPUTED_VALUE"""),"Alessandro Ferrarese") -> Alessandro Ferrarese | F16: =IFERROR(__xludf.DUMMYFUNCTION("""COMPUTED_VALUE"""),10000.0) -> 10000 | K16: =IFERROR(__xludf.DUMMYFUNCTION("""COMPUTED_VALUE"""),"Loris Tigli") -> Loris Tigli | L16: =IFERROR(__xludf.DUMMYFUNCTION("""COMPUTED_VALUE"""),50000.0) -> 50000
B17: =IFERROR(__xludf.DUMMYFUNCTION("""COMPUTED_VALUE"""),"Klaus Trophobico") -> Klaus Trophobico | C17: =IFERROR(__xludf.DUMMYFUNCTION("""COMPUTED_VALUE"""),50000.0) -> 50000 | E17: =IFERROR(__xludf.DUMMYFUNCTION("""COMPUTED_VALUE"""),"Mario Bochicchio") -> Mario Bochicchio | F17: =IFERROR(__xludf.DUMMYFUNCTION("""COMPUTED_VALUE"""),10000.0) -> 10000 | K17: =IFERROR(__xludf.DUMMYFUNCTION("""COMPUTED_VALUE"""),"Luca Pedroletti") -> Luca Pedroletti | L17: =IFERROR(__xludf.DUMMYFUNCTION("""COMPUTED_VALUE"""),50000.0) -> 50000
B18: =IFERROR(__xludf.DUMMYFUNCTION("""COMPUTED_VALUE"""),"Nicola Putton") -> Nicola Putton | C18: =IFERROR(__xludf.DUMMYFUNCTION("""COMPUTED_VALUE"""),50000.0) -> 50000 | E18: =IFERROR(__xludf.DUMMYFUNCTION("""COMPUTED_VALUE"""),"Tizio Caio") -> Tizio Caio | F18: =IFERROR(__xludf.DUMMYFUNCTION("""COMPUTED_VALUE"""),10000.0) -> 10000 | K18: =IFERROR(__xludf.DUMMYFUNCTION("""COMPUTED_VALUE"""),"Nicola Madeddu") -> Nicola Madeddu | L18: =IFERROR(__xludf.DUMMYFUNCTION("""COMPUTED_VALUE"""),50000.0) -> 50000
E19: =IFERROR(__xludf.DUMMYFUNCTION("""COMPUTED_VALUE"""),"Riccardo Todaro") -> Riccardo Todaro | F19: =IFERROR(__xludf.DUMMYFUNCTION("""COMPUTED_VALUE"""),5000.0) -> 5000 | K19: =IFERROR(__xludf.DUMMYFUNCTION("""COMPUTED_VALUE"""),"Nicola Putton") -> Nicola Putton | L19: =IFERROR(__xludf.DUMMYFUNCTION("""COMPUTED_VALUE"""),50000.0) -> 50000
E20: =IFERROR(__xludf.DUMMYFUNCTION("""COMPUTED_VALUE"""),"Loris Tigli") -> Loris Tigli | F20: =IFERROR(__xludf.DUMMYFUNCTION("""COMPUTED_VALUE"""),5000.0) -> 5000 | K20: =IFERROR(__xludf.DUMMYFUNCTION("""COMPUTED_VALUE"""),"Paola Alessandra Pisani") -> Paola Alessandra Pisani | L20: =IFERROR(__xludf.DUMMYFUNCTION("""COMPUTED_VALUE"""),50000.0) -> 50000
E21: =IFERROR(__xludf.DUMMYFUNCTION("""COMPUTED_VALUE"""),"Angela Iadicicco") -> Angela Iadicicco | F21: =IFERROR(__xludf.DUMMYFUNCTION("""COMPUTED_VALUE"""),5000.0) -> 5000 | K21: =IFERROR(__xludf.DUMMYFUNCTION("""COMPUTED_VALUE"""),"Riccardo Todaro") -> Riccardo Todaro | L21: =IFERROR(__xludf.DUMMYFUNCTION("""COMPUTED_VALUE"""),50000.0) -> 50000
L22: =IFERROR(__xludf.DUMMYFUNCTION("""COMPUTED_VALUE"""),50000.0) -> 50000
L23: =IFERROR(__xludf.DUMMYFUNCTION("""COMPUTED_VALUE"""),50000.0) -> 50000
L24: =IFERROR(__xludf.DUMMYFUNCTION("""COMPUTED_VALUE"""),50000.0) -> 50000
L25: =IFERROR(__xludf.DUMMYFUNCTION("""COMPUTED_VALUE"""),50000.0) -> 50000
L26: =IFERROR(__xludf.DUMMYFUNCTION("""COMPUTED_VALUE"""),50000.0) -> 50000
L27: =IFERROR(__xludf.DUMMYFUNCTION("""COMPUTED_VALUE"""),50000.0) -> 50000
L28: =IFERROR(__xludf.DUMMYFUNCTION("""COMPUTED_VALUE"""),50000.0) -> 50000
L29: =IFERROR(__xludf.DUMMYFUNCTION("""COMPUTED_VALUE"""),50000.0) -> 50000
L30: =IFERROR(__xludf.DUMMYFUNCTION("""COMPUTED_VALUE"""),50000.0) -> 50000
L31: =IFERROR(__xludf.DUMMYFUNCTION("""COMPUTED_VALUE"""),50000.0) -> 50000
L32: =IFERROR(__xludf.DUMMYFUNCTION("""COMPUTED_VALUE"""),50000.0) -> 50000
L33: =IFERROR(__xludf.DUMMYFUNCTION("""COMPUTED_VALUE"""),50000.0) -> 50000
... L42: =IFERROR(__xludf.DUMMYFUNCTION("""COMPUTED_VALUE"""),50000.0) -> 50000

Sheet Bonus Fedeltà
B2: Concorso Aggiornato | C2: 10 | E2: SEMPRE PRESENTI
E3: Utente | F3: Strike 1 | G3: Strike 2 | H3: Premio
B4: Alessandro Casiraro | D4: 1 | E4: Alessandro Gallo | H4: 50000
B5: Alessandro Gallo | D5: 2 | E5: Alessio Chiarelli | H5: 50000
B6: Alessio Chiarelli | D6: 3 | H6: 50000
B7: Alessio Costulo | D7: 4 | E7: Angela Iadicicco | H7: 50000
B8: Alessio Marchegiani | D8: 5 | E8: Antonio Cirino | F8: X | H8: 50000
B9: Angela Iadicicco | D9: 6 | H9: 50000
B10: Antonio Cirino | D10: 7 | E10: Daniele Greca | H10: 50000
B11: Daniele Greca | D11: 8 | H11: 50000
B12: Francesco Fusco | D12: 9 | E12: Francesco Fusco | H12: 50000
B13: Gaetano Baiamonte | D13: 10 | E13: Gaetano Baiamonte | H13: 50000
B14: Gianfranco Colucci | D14: 11 | E14: Gianfranco Colucci | H14: 50000
B15: Klaus Trophobico | D15: 12 | E15: Klaus Trophobico | H15: 50000
B16: Loris Tigli | D16: 13 | E16: Loris Tigli | H16: 50000
B17: Luca Marchetti | D17: 14 | E17: Luca Pedroletti | H17: 50000
B18: Luca Pedroletti | D18: 15 | E18: Nicola Madeddu | H18: 50000
B19: Nicola Madeddu | D19: 16 | E19: Nicola Putton | H19: 50000
B20: Nicola Putton | D20: 17 | E20: Paola Alessandra Pisani | H20: 50000
B21: Paola Alessandra Pisani | D21: 18 | E21: Riccardo Todaro | H21: 50000
B22: Raffaele Zicolella | D22: 19 | H22: 50000
B23: Riccado Todaro | D23: 20 | H23: 50000
B24: Tizio Caio | D24: 21 | H24: 50000
D25: 22 | H25: 50000
D26: 23 | H26: 50000
D27: 24 | H27: 50000
D28: 25 | H28: 50000
D29: 26 | H29: 50000
D30: 27 | H30: 50000
D31: 28 | H31: 50000
D32: 29 | H32: 50000
D33: 30 | H33: 50000
D34: 31 | H34: 50000
D35: 32 | H35: 50000
D36: 33 | H36: 50000
... D42: 39 | H42: 50000

Sheet Classifiche e premi
B1: Classifica Generale | E1: Classifica Generale | H1: Concorsi settimanali | K1: Bonus Fedeltà | N1: Guadagni Totali | Q1: Guadagni Finali
B2: =IFERROR(__xludf.DUMMYFUNCTION("UNIQUE(QUERY('Classifiche settimanali'!C4:C536, ""select Col1 where Col1 is not null and Col1<>'Utente' and Col1<>'1' and Col1<>'2' and Col1<>'3' and Col1<>'4' and Col1<>'5' and Col1<>'6' and Col1<>'7' and Col1<>'8' and Col1<>'9' and Col1<>'10'""))"),"Riccardo Ricci") -> Riccardo Ricci | C2: =IF(B2<>"", SUMIF('Classifiche settimanali'!C:E,B2,'Classifiche settimanali'!D:D),"") -> 25 | E2: =IFERROR(__xludf.DUMMYFUNCTION("UNIQUE(QUERY('Classifiche settimanali'!I4:I536, ""select Col1 where Col1 is not null and Col1<>'Utente' and Col1<>'1' and Col1<>'2' and Col1<>'3' and Col1<>'4' and Col1<>'5' and Col1<>'6' and Col1<>'7' and Col1<>'8' and Col1<>'9' and Col1<>'10'""))"),"Squadra") -> Squadra | F2: =IF(E2<>"", SUMIF('Classifiche settimanali'!I:K,E2,'Classifiche settimanali'!J:J),"") -> 0 | H2: =IFERROR(__xludf.DUMMYFUNCTION("UNIQUE(QUERY('Classifiche settimanali'!B4:C536, ""select Col2 where Col1 > 0""))"),"Riccardo Ricci") -> Riccardo Ricci | I2: =IF(H2="","", SUMIF('Classifiche settimanali'!C:E,H2,'Classifiche settimanali'!B:B)) -> 20000 | K2: =IFERROR(__xludf.DUMMYFUNCTION("(QUERY('Bonus Fedeltà'!$E$4:$H536, ""select Col1, Col4""))"),"Alessandro Gallo") -> Alessandro Gallo | L2: =IFERROR(__xludf.DUMMYFUNCTION("""COMPUTED_VALUE"""),50000.0) -> 50000 | N2: =IFERROR(__xludf.DUMMYFUNCTION("UNIQUE(QUERY(K2:L100,""select Col1""))"),"Alessandro Gallo") -> Alessandro Gallo | O2: =IF(N2="","", SUMIF(Premi!$E$4:$E536,N2,Premi!$F$4:$F536) + SUMIF(Premi!$H$4:$H536,N2,Premi!$I$4:$I536) + SUMIF(Premi!$K$4:$K536,N2,Premi!$L$4:$L536)) -> 50000 | Q2: =IFERROR(__xludf.DUMMYFUNCTION("UNIQUE(QUERY(N2:O100,""select Col1,Col2""))"),"Alessandro Gallo") -> Alessandro Gallo | R2: =IFERROR(__xludf.DUMMYFUNCTION("""COMPUTED_VALUE"""),50000.0) -> 50000
B3: =IFERROR(__xludf.DUMMYFUNCTION("""COMPUTED_VALUE"""),"Stefano Serra") -> Stefano Serra | C3: =IF(B3<>"", SUMIF('Classifiche settimanali'!C:E,B3,'Classifiche settimanali'!D:D),"") -> 20 | E3: =IFERROR(__xludf.DUMMYFUNCTION("""COMPUTED_VALUE"""),"Cremonese") -> Cremonese | F3: =IF(E3<>"", SUMIF('Classifiche settimanali'!I:K,E3,'Classifiche settimanali'!J:J),"") -> 26 | H3: =IFERROR(__xludf.DUMMYFUNCTION("""COMPUTED_VALUE"""),"Stefano Serra") -> Stefano Serra | I3: =IF(H3="","", SUMIF('Classifiche settimanali'!C:E,H3,'Classifiche settimanali'!B:B)) -> 10000 | K3: =IFERROR(__xludf.DUMMYFUNCTION("""COMPUTED_VALUE"""),"Alessio Chiarelli") -> Alessio Chiarelli | L3: =IFERROR(__xludf.DUMMYFUNCTION("""COMPUTED_VALUE"""),50000.0) -> 50000 | N3: =IFERROR(__xludf.DUMMYFUNCTION("""COMPUTED_VALUE"""),"Alessio Chiarelli") -> Alessio Chiarelli | O3: =IF(N3="","", SUMIF(Premi!$E$4:$E536,N3,Premi!$F$4:$F536) + SUMIF(Premi!$H$4:$H536,N3,Premi!$I$4:$I536) + SUMIF(Premi!$K$4:$K536,N3,Premi!$L$4:$L536)) -> 50000 | Q3: =IFERROR(__xludf.DUMMYFUNCTION("""COMPUTED_VALUE"""),"Alessio Chiarelli") -> Alessio Chiarelli | R3: =IFERROR(__xludf.DUMMYFUNCTION("""COMPUTED_VALUE"""),50000.0) -> 50000
B4: =IFERROR(__xludf.DUMMYFUNCTION("""COMPUTED_VALUE"""),"Raffaele Zicolella") -> Raffaele Zicolella | C4: =IF(B4<>"", SUMIF('Classifiche settimanali'!C:E,B4,'Classifiche settimanali'!D:D),"") -> 47 | E4: =IFERROR(__xludf.DUMMYFUNCTION("""COMPUTED_VALUE"""),"Padova") -> Padova | F4: =IF(E4<>"", SUMIF('Classifiche settimanali'!I:K,E4,'Classifiche settimanali'!J:J),"") -> 42 | H4: =IFERROR(__xludf.DUMMYFUNCTION("""COMPUTED_VALUE"""),"Raffaele Zicolella") -> Raffaele Zicolella | I4: =IF(H4="","", SUMIF('Classifiche settimanali'!C:E,H4,'Classifiche settimanali'!B:B)) -> 25000 | L4: =IFERROR(__xludf.DUMMYFUNCTION("""COMPUTED_VALUE"""),50000.0) -> 50000 | O4: =IF(N4="","", SUMIF(Premi!$E$4:$E536,N4,Premi!$F$4:$F536) + SUMIF(Premi!$H$4:$H536,N4,Premi!$I$4:$I536) + SUMIF(Premi!$K$4:$K536,N4,Premi!$L$4:$L536))
B5: =IFERROR(__xludf.DUMMYFUNCTION("""COMPUTED_VALUE"""),"Daniele Dottori") -> Daniele Dottori | C5: =IF(B5<>"", SUMIF('Classifiche settimanali'!C:E,B5,'Classifiche settimanali'!D:D),"") -> 19 | E5: =IFERROR(__xludf.DUMMYFUNCTION("""COMPUTED_VALUE"""),"Como") -> Como | F5: =IF(E5<>"", SUMIF('Classifiche settimanali'!I:K,E5,'Classifiche settimanali'!J:J),"") -> 16 | H5: =IFERROR(__xludf.DUMMYFUNCTION("""COMPUTED_VALUE"""),"Gaetano Baiamonte") -> Gaetano Baiamonte | I5: =IF(H5="","", SUMIF('Classifiche settimanali'!C:E,H5,'Classifiche settimanali'!B:B)) -> 55000 | K5: =IFERROR(__xludf.DUMMYFUNCTION("""COMPUTED_VALUE"""),"Angela Iadicicco") -> Angela Iadicicco | L5: =IFERROR(__xludf.DUMMYFUNCTION("""COMPUTED_VALUE"""),50000.0) -> 50000 | N5: =IFERROR(__xludf.DUMMYFUNCTION("""COMPUTED_VALUE"""),"Angela Iadicicco") -> Angela Iadicicco | O5: =IF(N5="","", SUMIF(Premi!$E$4:$E536,N5,Premi!$F$4:$F536) + SUMIF(Premi!$H$4:$H536,N5,Premi!$I$4:$I536) + SUMIF(Premi!$K$4:$K536,N5,Premi!$L$4:$L536)) -> 55000 | Q5: =IFERROR(__xludf.DUMMYFUNCTION("""COMPUTED_VALUE"""),"Angela Iadicicco") -> Angela Iadicicco | R5: =IFERROR(__xludf.DUMMYFUNCTION("""COMPUTED_VALUE"""),55000.0) -> 55000
B6: =IFERROR(__xludf.DUMMYFUNCTION("""COMPUTED_VALUE"""),"Nicola Putton") -> Nicola Putton | C6: =IF(B6<>"", SUMIF('Classifiche settimanali'!C:E,B6,'Classifiche settimanali'!D:D),"") -> 27 | E6: =IFERROR(__xludf.DUMMYFUNCTION("""COMPUTED_VALUE"""),"Mantova") -> Mantova | F6: =IF(E6<>"", SUMIF('Classifiche settimanali'!I:K,E6,'Classifiche settimanali'!J:J),"") -> 51 | H6: =IFERROR(__xludf.DUMMYFUNCTION("""COMPUTED_VALUE"""),"Nicola Madeddu") -> Nicola Madeddu | I6: =IF(H6="","", SUMIF('Classifiche settimanali'!C:E,H6,'Classifiche settimanali'!B:B)) -> 50000 | K6: =IFERROR(__xludf.DUMMYFUNCTION("""COMPUTED_VALUE"""),"Antonio Cirino") -> Antonio Cirino | L6: =IFERROR(__xludf.DUMMYFUNCTION("""COMPUTED_VALUE"""),50000.0) -> 50000 | N6: =IFERROR(__xludf.DUMMYFUNCTION("""COMPUTED_VALUE"""),"Antonio Cirino") -> Antonio Cirino | O6: =IF(N6="","", SUMIF(Premi!$E$4:$E536,N6,Premi!$F$4:$F536) + SUMIF(Premi!$H$4:$H536,N6,Premi!$I$4:$I536) + SUMIF(Premi!$K$4:$K536,N6,Premi!$L$4:$L536)) -> 65000 | Q6: =IFERROR(__xludf.DUMMYFUNCTION("""COMPUTED_VALUE"""),"Antonio Cirino") -> Antonio Cirino | R6: =IFERROR(__xludf.DUMMYFUNCTION("""COMPUTED_VALUE"""),65000.0) -> 65000
B7: =IFERROR(__xludf.DUMMYFUNCTION("""COMPUTED_VALUE"""),"Gaetano Baiamonte") -> Gaetano Baiamonte | C7: =IF(B7<>"", SUMIF('Classifiche settimanali'!C:E,B7,'Classifiche settimanali'!D:D),"") -> 95 | E7: =IFERROR(__xludf.DUMMYFUNCTION("""COMPUTED_VALUE"""),"Garda") -> Garda | F7: =IF(E7<>"", SUMIF('Classifiche settimanali'!I:K,E7,'Classifiche settimanali'!J:J),"") -> 35 | H7: =IFERROR(__xludf.DUMMYFUNCTION("""COMPUTED_VALUE"""),"Luca Pedroletti") -> Luca Pedroletti | I7: =IF(H7="","", SUMIF('Classifiche settimanali'!C:E,H7,'Classifiche settimanali'!B:B)) -> 25000 | L7: =IFERROR(__xludf.DUMMYFUNCTION("""COMPUTED_VALUE"""),50000.0) -> 50000 | N7: =IFERROR(__xludf.DUMMYFUNCTION("""COMPUTED_VALUE"""),"Daniele Greca") -> Daniele Greca | O7: =IF(N7="","", SUMIF(Premi!$E$4:$E536,N7,Premi!$F$4:$F536) + SUMIF(Premi!$H$4:$H536,N7,Premi!$I$4:$I536) + SUMIF(Premi!$K$4:$K536,N7,Premi!$L$4:$L536)) -> 70000 | Q7: =IFERROR(__xludf.DUMMYFUNCTION("""COMPUTED_VALUE"""),"Daniele Greca") -> Daniele Greca | R7: =IFERROR(__xludf.DUMMYFUNCTION("""COMPUTED_VALUE"""),70000.0) -> 70000
B8: =IFERROR(__xludf.DUMMYFUNCTION("""COMPUTED_VALUE"""),"Alessandro Casiraro") -> Alessandro Casiraro | C8: =IF(B8<>"", SUMIF('Classifiche settimanali'!C:E,B8,'Classifiche settimanali'!D:D),"") -> 44 | E8: =IFERROR(__xludf.DUMMYFUNCTION("""COMPUTED_VALUE"""),"RavennaZ") -> RavennaZ | F8: =IF(E8<>"", SUMIF('Classifiche settimanali'!I:K,E8,'Classifiche settimanali'!J:J),"") -> 178 | H8: =IFERROR(__xludf.DUMMYFUNCTION("""COMPUTED_VALUE"""),"Gianfranco Colucci") -> Gianfranco Colucci | I8: =IF(H8="","", SUMIF('Classifiche settimanali'!C:E,H8,'Classifiche settimanali'!B:B)) -> 20000 | K8: =IFERROR(__xludf.DUMMYFUNCTION("""COMPUTED_VALUE"""),"Daniele Greca") -> Daniele Greca | L8: =IFERROR(__xludf.DUMMYFUNCTION("""COMPUTED_VALUE"""),50000.0) -> 50000 | N8: =IFERROR(__xludf.DUMMYFUNCTION("""COMPUTED_VALUE"""),"Francesco Fusco") -> Francesco Fusco | O8: =IF(N8="","", SUMIF(Premi!$E$4:$E536,N8,Premi!$F$4:$F536) + SUMIF(Premi!$H$4:$H536,N8,Premi!$I$4:$I536) + SUMIF(Premi!$K$4:$K536,N8,Premi!$L$4:$L536)) -> 105000 | Q8: =IFERROR(__xludf.DUMMYFUNCTION("""COMPUTED_VALUE"""),"Francesco Fusco") -> Francesco Fusco | R8: =IFERROR(__xludf.DUMMYFUNCTION("""COMPUTED_VALUE"""),105000.0) -> 105000
B9: =IFERROR(__xludf.DUMMYFUNCTION("""COMPUTED_VALUE"""),"Nicola Madeddu") -> Nicola Madeddu | C9: =IF(B9<>"", SUMIF('Classifiche settimanali'!C:E,B9,'Classifiche settimanali'!D:D),"") -> 125 | E9: =IFERROR(__xludf.DUMMYFUNCTION("""COMPUTED_VALUE"""),"Catanzaro") -> Catanzaro | F9: =IF(E9<>"", SUMIF('Classifiche settimanali'!I:K,E9,'Classifiche settimanali'!J:J),"") -> 49 | H9: =IFERROR(__xludf.DUMMYFUNCTION("""COMPUTED_VALUE"""),"Alessandro Ferrarese") -> Alessandro Ferrarese | I9: =IF(H9="","", SUMIF('Classifiche settimanali'!C:E,H9,'Classifiche settimanali'!B:B)) -> 10000 | L9: =IFERROR(__xludf.DUMMYFUNCTION("""COMPUTED_VALUE"""),50000.0) -> 50000 | N9: =IFERROR(__xludf.DUMMYFUNCTION("""COMPUTED_VALUE"""),"Gaetano Baiamonte") -> Gaetano Baiamonte | O9: =IF(N9="","", SUMIF(Premi!$E$4:$E536,N9,Premi!$F$4:$F536) + SUMIF(Premi!$H$4:$H536,N9,Premi!$I$4:$I536) + SUMIF(Premi!$K$4:$K536,N9,Premi!$L$4:$L536)) -> 255000 | Q9: =IFERROR(__xludf.DUMMYFUNCTION("""COMPUTED_VALUE"""),"Gaetano Baiamonte") -> Gaetano Baiamonte | R9: =IFERROR(__xludf.DUMMYFUNCTION("""COMPUTED_VALUE"""),255000.0) -> 255000
B10: =IFERROR(__xludf.DUMMYFUNCTION("""COMPUTED_VALUE"""),"Tizio Caio") -> Tizio Caio | C10: =IF(B10<>"", SUMIF('Classifiche settimanali'!C:E,B10,'Classifiche settimanali'!D:D),"") -> 55 | E10: =IFERROR(__xludf.DUMMYFUNCTION("""COMPUTED_VALUE"""),"Cervia") -> Cervia | F10: =IF(E10<>"", SUMIF('Classifiche settimanali'!I:K,E10,'Classifiche settimanali'!J:J),"") -> 63 | H10: =IFERROR(__xludf.DUMMYFUNCTION("""COMPUTED_VALUE"""),"Alessandro Casiraro") -> Alessandro Casiraro | I10: =IF(H10="","", SUMIF('Classifiche settimanali'!C:E,H10,'Classifiche settimanali'!B:B)) -> 20000 | K10: =IFERROR(__xludf.DUMMYFUNCTION("""COMPUTED_VALUE"""),"Francesco Fusco") -> Francesco Fusco | L10: =IFERROR(__xludf.DUMMYFUNCTION("""COMPUTED_VALUE"""),50000.0) -> 50000 | N10: =IFERROR(__xludf.DUMMYFUNCTION("""COMPUTED_VALUE"""),"Gianfranco Colucci") -> Gianfranco Colucci | O10: =IF(N10="","", SUMIF(Premi!$E$4:$E536,N10,Premi!$F$4:$F536) + SUMIF(Premi!$H$4:$H536,N10,Premi!$I$4:$I536) + SUMIF(Premi!$K$4:$K536,N10,Premi!$L$4:$L536)) -> 170000 | Q10: =IFERROR(__xludf.DUMMYFUNCTION("""COMPUTED_VALUE"""),"Gianfranco Colucci") -> Gianfranco Colucci | R10: =IFERROR(__xludf.DUMMYFUNCTION("""COMPUTED_VALUE"""),170000.0) -> 170000
B11: =IFERROR(__xludf.DUMMYFUNCTION("""COMPUTED_VALUE"""),"Luca Pedroletti") -> Luca Pedroletti | C11: =IF(B11<>"", SUMIF('Classifiche settimanali'!C:E,B11,'Classifiche settimanali'!D:D),"") -> 63 | E11: =IFERROR(__xludf.DUMMYFUNCTION("""COMPUTED_VALUE"""),"Reggina") -> Reggina | F11: =IF(E11<>"", SUMIF('Classifiche settimanali'!I:K,E11,'Classifiche settimanali'!J:J),"") -> 72 | H11: =IFERROR(__xludf.DUMMYFUNCTION("""COMPUTED_VALUE"""),"Riccardo Todaro") -> Riccardo Todaro | I11: =IF(H11="","", SUMIF('Classifiche settimanali'!C:E,H11,'Classifiche settimanali'!B:B)) -> 5000 | K11: =IFERROR(__xludf.DUMMYFUNCTION("""COMPUTED_VALUE"""),"Gaetano Baiamonte") -> Gaetano Baiamonte | L11: =IFERROR(__xludf.DUMMYFUNCTION("""COMPUTED_VALUE"""),50000.0) -> 50000 | N11: =IFERROR(__xludf.DUMMYFUNCTION("""COMPUTED_VALUE"""),"Klaus Trophobico") -> Klaus Trophobico | O11: =IF(N11="","", SUMIF(Premi!$E$4:$E536,N11,Premi!$F$4:$F536) + SUMIF(Premi!$H$4:$H536,N11,Premi!$I$4:$I536) + SUMIF(Premi!$K$4:$K536,N11,Premi!$L$4:$L536)) -> 50000 | Q11: =IFERROR(__xludf.DUMMYFUNCTION("""COMPUTED_VALUE"""),"Klaus Trophobico") -> Klaus Trophobico | R11: =IFERROR(__xludf.DUMMYFUNCTION("""COMPUTED_VALUE"""),50000.0) -> 50000
B12: =IFERROR(__xludf.DUMMYFUNCTION("""COMPUTED_VALUE"""),"Alessandro Gallo") -> Alessandro Gallo | C12: =IF(B12<>"", SUMIF('Classifiche settimanali'!C:E,B12,'Classifiche settimanali'!D:D),"") -> 30 | E12: =IFERROR(__xludf.DUMMYFUNCTION("""COMPUTED_VALUE"""),"Torino") -> Torino | F12: =IF(E12<>"", SUMIF('Classifiche settimanali'!I:K,E12,'Classifiche settimanali'!J:J),"") -> 48 | H12: =IFERROR(__xludf.DUMMYFUNCTION("""COMPUTED_VALUE"""),"Daniele Greca") -> Daniele Greca | I12: =IF(H12="","", SUMIF('Classifiche settimanali'!C:E,H12,'Classifiche settimanali'!B:B)) -> 20000 | K12: =IFERROR(__xludf.DUMMYFUNCTION("""COMPUTED_VALUE"""),"Gianfranco Colucci") -> Gianfranco Colucci | L12: =IFERROR(__xludf.DUMMYFUNCTION("""COMPUTED_VALUE"""),50000.0) -> 50000 | N12: =IFERROR(__xludf.DUMMYFUNCTION("""COMPUTED_VALUE"""),"Loris Tigli") -> Loris Tigli | O12: =IF(N12="","", SUMIF(Premi!$E$4:$E536,N12,Premi!$F$4:$F536) + SUMIF(Premi!$H$4:$H536,N12,Premi!$I$4:$I536) + SUMIF(Premi!$K$4:$K536,N12,Premi!$L$4:$L536)) -> 105000 | Q12: =IFERROR(__xludf.DUMMYFUNCTION("""COMPUTED_VALUE"""),"Loris Tigli") -> Loris Tigli | R12: =IFERROR(__xludf.DUMMYFUNCTION("""COMPUTED_VALUE"""),105000.0) -> 105000
B13: =IFERROR(__xludf.DUMMYFUNCTION("""COMPUTED_VALUE"""),"Gianfranco Colucci") -> Gianfranco Colucci | C13: =IF(B13<>"", SUMIF('Classifiche settimanali'!C:E,B13,'Classifiche settimanali'!D:D),"") -> 66 | E13: =IFERROR(__xludf.DUMMYFUNCTION("""COMPUTED_VALUE"""),"Bologna") -> Bologna | F13: =IF(E13<>"", SUMIF('Classifiche settimanali'!I:K,E13,'Classifiche settimanali'!J:J),"") -> 105 | H13: =IFERROR(__xludf.DUMMYFUNCTION("""COMPUTED_VALUE"""),"Mario Bochicchio") -> Mario Bochicchio | I13: =IF(H13="","", SUMIF('Classifiche settimanali'!C:E,H13,'Classifiche settimanali'!B:B)) -> 10000 | K13: =IFERROR(__xludf.DUMMYFUNCTION("""COMPUTED_VALUE"""),"Klaus Trophobico") -> Klaus Trophobico | L13: =IFERROR(__xludf.DUMMYFUNCTION("""COMPUTED_VALUE"""),50000.0) -> 50000 | N13: =IFERROR(__xludf.DUMMYFUNCTION("""COMPUTED_VALUE"""),"Luca Pedroletti") -> Luca Pedroletti | O13: =IF(N13="","", SUMIF(Premi!$E$4:$E536,N13,Premi!$F$4:$F536) + SUMIF(Premi!$H$4:$H536,N13,Premi!$I$4:$I536) + SUMIF(Premi!$K$4:$K536,N13,Premi!$L$4:$L536)) -> 145000 | Q13: =IFERROR(__xludf.DUMMYFUNCTION("""COMPUTED_VALUE"""),"Luca Pedroletti") -> Luca Pedroletti | R13: =IFERROR(__xludf.DUMMYFUNCTION("""COMPUTED_VALUE"""),145000.0) -> 145000
B14: =IFERROR(__xludf.DUMMYFUNCTION("""COMPUTED_VALUE"""),"Angela Iadicicco") -> Angela Iadicicco | C14: =IF(B14<>"", SUMIF('Classifiche settimanali'!C:E,B14,'Classifiche settimanali'!D:D),"") -> 43 | E14: =IFERROR(__xludf.DUMMYFUNCTION("""COMPUTED_VALUE"""),"Mambo") -> Mambo | F14: =IF(E14<>"", SUMIF('Classifiche settimanali'!I:K,E14,'Classifiche settimanali'!J:J),"") -> 75 | H14: =IFERROR(__xludf.DUMMYFUNCTION("""COMPUTED_VALUE"""),"Francesco Fusco") -> Francesco Fusco | I14: =IF(H14="","", SUMIF('Classifiche settimanali'!C:E,H14,'Classifiche settimanali'!B:B)) -> 15000 | K14: =IFERROR(__xludf.DUMMYFUNCTION("""COMPUTED_VALUE"""),"Loris Tigli") -> Loris Tigli | L14: =IFERROR(__xludf.DUMMYFUNCTION("""COMPUTED_VALUE"""),50000.0) -> 50000 | N14: =IFERROR(__xludf.DUMMYFUNCTION("""COMPUTED_VALUE"""),"Nicola Madeddu") -> Nicola Madeddu | O14: =IF(N14="","", SUMIF(Premi!$E$4:$E536,N14,Premi!$F$4:$F536) + SUMIF(Premi!$H$4:$H536,N14,Premi!$I$4:$I536) + SUMIF(Premi!$K$4:$K536,N14,Premi!$L$4:$L536)) -> 300000 | Q14: =IFERROR(__xludf.DUMMYFUNCTION("""COMPUTED_VALUE"""),"Nicola Madeddu") -> Nicola Madeddu | R14: =IFERROR(__xludf.DUMMYFUNCTION("""COMPUTED_VALUE"""),300000.0) -> 300000
B15: =IFERROR(__xludf.DUMMYFUNCTION("""COMPUTED_VALUE"""),"Alessio Marchegiani") -> Alessio Marchegiani | C15: =IF(B15<>"", SUMIF('Classifiche settimanali'!C:E,B15,'Classifiche settimanali'!D:D),"") -> 25 | E15: =IFERROR(__xludf.DUMMYFUNCTION("""COMPUTED_VALUE"""),"Parma") -> Parma | F15: =IF(E15<>"", SUMIF('Classifiche settimanali'!I:K,E15,'Classifiche settimanali'!J:J),"") -> 34 | H15: =IFERROR(__xludf.DUMMYFUNCTION("""COMPUTED_VALUE"""),"Paola Alessandra Pisani") -> Paola Alessandra Pisani | I15: =IF(H15="","", SUMIF('Classifiche settimanali'!C:E,H15,'Classifiche settimanali'!B:B)) -> 30000 | K15: =IFERROR(__xludf.DUMMYFUNCTION("""COMPUTED_VALUE"""),"Luca Pedroletti") -> Luca Pedroletti | L15: =IFERROR(__xludf.DUMMYFUNCTION("""COMPUTED_VALUE"""),50000.0) -> 50000 | N15: =IFERROR(__xludf.DUMMYFUNCTION("""COMPUTED_VALUE"""),"Nicola Putton") -> Nicola Putton | O15: =IF(N15="","", SUMIF(Premi!$E$4:$E536,N15,Premi!$F$4:$F536) + SUMIF(Premi!$H$4:$H536,N15,Premi!$I$4:$I536) + SUMIF(Premi!$K$4:$K536,N15,Premi!$L$4:$L536)) -> 50000 | Q15: =IFERROR(__xludf.DUMMYFUNCTION("""COMPUTED_VALUE"""),"Nicola Putton") -> Nicola Putton | R15: =IFERROR(__xludf.DUMMYFUNCTION("""COMPUTED_VALUE"""),50000.0) -> 50000
B16: =IFERROR(__xludf.DUMMYFUNCTION("""COMPUTED_VALUE"""),"Davide Costarella") -> Davide Costarella | C16: =IF(B16<>"", SUMIF('Classifiche settimanali'!C:E,B16,'Classifiche settimanali'!D:D),"") -> 1 | E16: =IFERROR(__xludf.DUMMYFUNCTION("""COMPUTED_VALUE"""),"Entella") -> Entella | F16: =IF(E16<>"", SUMIF('Classifiche settimanali'!I:K,E16,'Classifiche settimanali'!J:J),"") -> 4 | H16: =IFERROR(__xludf.DUMMYFUNCTION("""COMPUTED_VALUE"""),"Loris Tigli") -> Loris Tigli | I16: =IF(H16="","", SUMIF('Classifiche settimanali'!C:E,H16,'Classifiche settimanali'!B:B)) -> 5000 | K16: =IFERROR(__xludf.DUMMYFUNCTION("""COMPUTED_VALUE"""),"Nicola Madeddu") -> Nicola Madeddu | L16: =IFERROR(__xludf.DUMMYFUNCTION("""COMPUTED_VALUE"""),50000.0) -> 50000 | N16: =IFERROR(__xludf.DUMMYFUNCTION("""COMPUTED_VALUE"""),"Paola Alessandra Pisani") -> Paola Alessandra Pisani | O16: =IF(N16="","", SUMIF(Premi!$E$4:$E536,N16,Premi!$F$4:$F536) + SUMIF(Premi!$H$4:$H536,N16,Premi!$I$4:$I536) + SUMIF(Premi!$K$4:$K536,N16,Premi!$L$4:$L536)) -> 110000 | Q16: =IFERROR(__xludf.DUMMYFUNCTION("""COMPUTED_VALUE"""),"Paola Alessandra Pisani") -> Paola Alessandra Pisani | R16: =IFERROR(__xludf.DUMMYFUNCTION("""COMPUTED_VALUE"""),110000.0) -> 110000
B17: =IFERROR(__xludf.DUMMYFUNCTION("""COMPUTED_VALUE"""),"Alessandro Ferrarese") -> Alessandro Ferrarese | C17: =IF(B17<>"", SUMIF('Classifiche settimanali'!C:E,B17,'Classifiche settimanali'!D:D),"") -> 20 | E17: =IFERROR(__xludf.DUMMYFUNCTION("""COMPUTED_VALUE"""),"Progetto Gaming") -> Progetto Gaming | F17: =IF(E17<>"", SUMIF('Classifiche settimanali'!I:K,E17,'Classifiche settimanali'!J:J),"") -> 79 | H17: =IFERROR(__xludf.DUMMYFUNCTION("""COMPUTED_VALUE"""),"Antonio Cirino") -> Antonio Cirino | I17: =IF(H17="","", SUMIF('Classifiche settimanali'!C:E,H17,'Classifiche settimanali'!B:B)) -> 15000 | K17: =IFERROR(__xludf.DUMMYFUNCTION("""COMPUTED_VALUE"""),"Nicola Putton") -> Nicola Putton | L17: =IFERROR(__xludf.DUMMYFUNCTION("""COMPUTED_VALUE"""),50000.0) -> 50000 | N17: =IFERROR(__xludf.DUMMYFUNCTION("""COMPUTED_VALUE"""),"Riccardo Todaro") -> Riccardo Todaro | O17: =IF(N17="","", SUMIF(Premi!$E$4:$E536,N17,Premi!$F$4:$F536) + SUMIF(Premi!$H$4:$H536,N17,Premi!$I$4:$I536) + SUMIF(Premi!$K$4:$K536,N17,Premi!$L$4:$L536)) -> 55000 | Q17: =IFERROR(__xludf.DUMMYFUNCTION("""COMPUTED_VALUE"""),"Riccardo Todaro") -> Riccardo Todaro | R17: =IFERROR(__xludf.DUMMYFUNCTION("""COMPUTED_VALUE"""),55000.0) -> 55000
B18: =IFERROR(__xludf.DUMMYFUNCTION("""COMPUTED_VALUE"""),"Klaus Trophobico") -> Klaus Trophobico | C18: =IF(B18<>"", SUMIF('Classifiche settimanali'!C:E,B18,'Classifiche settimanali'!D:D),"") -> 27 | E18: =IFERROR(__xludf.DUMMYFUNCTION("""COMPUTED_VALUE"""),"Chievo") -> Chievo | F18: =IF(E18<>"", SUMIF('Classifiche settimanali'!I:K,E18,'Classifiche settimanali'!J:J),"") -> 30 | H18: =IFERROR(__xludf.DUMMYFUNCTION("""COMPUTED_VALUE"""),"Angela Iadicicco") -> Angela Iadicicco | I18: =IF(H18="","", SUMIF('Classifiche settimanali'!C:E,H18,'Classifiche settimanali'!B:B)) -> 5000 | K18: =IFERROR(__xludf.DUMMYFUNCTION("""COMPUTED_VALUE"""),"Paola Alessandra Pisani") -> Paola Alessandra Pisani | L18: =IFERROR(__xludf.DUMMYFUNCTION("""COMPUTED_VALUE"""),50000.0) -> 50000 | O18: =IF(N18="","", SUMIF(Premi!$E$4:$E536,N18,Premi!$F$4:$F536) + SUMIF(Premi!$H$4:$H536,N18,Premi!$I$4:$I536) + SUMIF(Premi!$K$4:$K536,N18,Premi!$L$4:$L536))
B19: =IFERROR(__xludf.DUMMYFUNCTION("""COMPUTED_VALUE"""),"Edoardo Marzulli") -> Edoardo Marzulli | C19: =IF(B19<>"", SUMIF('Classifiche settimanali'!C:E,B19,'Classifiche settimanali'!D:D),"") -> 11 | E19: =IFERROR(__xludf.DUMMYFUNCTION("""COMPUTED_VALUE"""),"Livorno") -> Livorno | F19: =IF(E19<>"", SUMIF('Classifiche settimanali'!I:K,E19,'Classifiche settimanali'!J:J),"") -> 20 | H19: =IFERROR(__xludf.DUMMYFUNCTION("""COMPUTED_VALUE"""),"Tizio Caio") -> Tizio Caio | I19: =IF(H19="","", SUMIF('Classifiche settimanali'!C:E,H19,'Classifiche settimanali'!B:B)) -> 10000 | K19: =IFERROR(__xludf.DUMMYFUNCTION("""COMPUTED_VALUE"""),"Riccardo Todaro") -> Riccardo Todaro | L19: =IFERROR(__xludf.DUMMYFUNCTION("""COMPUTED_VALUE"""),50000.0) -> 50000 | O19: =IF(N19="","", SUMIF(Premi!$E$4:$E536,N19,Premi!$F$4:$F536) + SUMIF(Premi!$H$4:$H536,N19,Premi!$I$4:$I536) + SUMIF(Premi!$K$4:$K536,N19,Premi!$L$4:$L536))
B20: =IFERROR(__xludf.DUMMYFUNCTION("""COMPUTED_VALUE"""),"Francesco Siciliano") -> Francesco Siciliano | C20: =IF(B20<>"", SUMIF('Classifiche settimanali'!C:E,B20,'Classifiche settimanali'!D:D),"") -> 8 | E20: =IFERROR(__xludf.DUMMYFUNCTION("""COMPUTED_VALUE"""),"Modena") -> Modena | F20: =IF(E20<>"", SUMIF('Classifiche settimanali'!I:K,E20,'Classifiche settimanali'!J:J),"") -> 11 | I20: =IF(H20="","", SUMIF('Classifiche settimanali'!C:E,H20,'Classifiche settimanali'!B:B)) | L20: =IFERROR(__xludf.DUMMYFUNCTION("""COMPUTED_VALUE"""),50000.0) -> 50000 | O20: =IF(N20="","", SUMIF(Premi!$E$4:$E536,N20,Premi!$F$4:$F536) + SUMIF(Premi!$H$4:$H536,N20,Premi!$I$4:$I536) + SUMIF(Premi!$K$4:$K536,N20,Premi!$L$4:$L536))
B21: =IFERROR(__xludf.DUMMYFUNCTION("""COMPUTED_VALUE"""),"Alessio Costulo") -> Alessio Costulo | C21: =IF(B21<>"", SUMIF('Classifiche settimanali'!C:E,B21,'Classifiche settimanali'!D:D),"") -> 14 | E21: =IFERROR(__xludf.DUMMYFUNCTION("""COMPUTED_VALUE"""),"VP") -> VP | F21: =IF(E21<>"", SUMIF('Classifiche settimanali'!I:K,E21,'Classifiche settimanali'!J:J),"") -> 8 | H21: =IFERROR(__xludf.DUMMYFUNCTION("""COMPUTED_VALUE"""),"#REF!") -> #REF! | I21: =IF(H21="","", SUMIF('Classifiche settimanali'!C:E,H21,'Classifiche settimanali'!B:B)) -> 140000 | L21: =IFERROR(__xludf.DUMMYFUNCTION("""COMPUTED_VALUE"""),50000.0) -> 50000 | O21: =IF(N21="","", SUMIF(Premi!$E$4:$E536,N21,Premi!$F$4:$F536) + SUMIF(Premi!$H$4:$H536,N21,Premi!$I$4:$I536) + SUMIF(Premi!$K$4:$K536,N21,Premi!$L$4:$L536))
B22: =IFERROR(__xludf.DUMMYFUNCTION("""COMPUTED_VALUE"""),"Marco Bortolotti") -> Marco Bortolotti | C22: =IF(B22<>"", SUMIF('Classifiche settimanali'!C:E,B22,'Classifiche settimanali'!D:D),"") -> 2 | E22: =IFERROR(__xludf.DUMMYFUNCTION("""COMPUTED_VALUE"""),"Piacenza") -> Piacenza | F22: =IF(E22<>"", SUMIF('Classifiche settimanali'!I:K,E22,'Classifiche settimanali'!J:J),"") -> 2 | I22: =IF(H22="","", SUMIF('Classifiche settimanali'!C:E,H22,'Classifiche settimanali'!B:B)) | L22: =IFERROR(__xludf.DUMMYFUNCTION("""COMPUTED_VALUE"""),50000.0) -> 50000 | O22: =IF(N22="","", SUMIF(Premi!$E$4:$E536,N22,Premi!$F$4:$F536) + SUMIF(Premi!$H$4:$H536,N22,Premi!$I$4:$I536) + SUMIF(Premi!$K$4:$K536,N22,Premi!$L$4:$L536))
B23: =IFERROR(__xludf.DUMMYFUNCTION("""COMPUTED_VALUE"""),"Riccardo Todaro") -> Riccardo Todaro | C23: =IF(B23<>"", SUMIF('Classifiche settimanali'!C:E,B23,'Classifiche settimanali'!D:D),"") -> 30 | E23: =IFERROR(__xludf.DUMMYFUNCTION("""COMPUTED_VALUE"""),"Alessandria") -> Alessandria | F23: =IF(E23<>"", SUMIF('Classifiche settimanali'!I:K,E23,'Classifiche settimanali'!J:J),"") -> 39 | I23: =IF(H23="","", SUMIF('Classifiche settimanali'!C:E,H23,'Classifiche settimanali'!B:B)) | L23: =IFERROR(__xludf.DUMMYFUNCTION("""COMPUTED_VALUE"""),50000.0) -> 50000 | O23: =IF(N23="","", SUMIF(Premi!$E$4:$E536,N23,Premi!$F$4:$F536) + SUMIF(Premi!$H$4:$H536,N23,Premi!$I$4:$I536) + SUMIF(Premi!$K$4:$K536,N23,Premi!$L$4:$L536))
B24: =IFERROR(__xludf.DUMMYFUNCTION("""COMPUTED_VALUE"""),"Loris Tigli") -> Loris Tigli | C24: =IF(B24<>"", SUMIF('Classifiche settimanali'!C:E,B24,'Classifiche settimanali'!D:D),"") -> 52 | E24: =IFERROR(__xludf.DUMMYFUNCTION("""COMPUTED_VALUE"""),"Cesena") -> Cesena | F24: =IF(E24<>"", SUMIF('Classifiche settimanali'!I:K,E24,'Classifiche settimanali'!J:J),"") -> 63 | I24: =IF(H24="","", SUMIF('Classifiche settimanali'!C:E,H24,'Classifiche settimanali'!B:B)) | L24: =IFERROR(__xludf.DUMMYFUNCTION("""COMPUTED_VALUE"""),50000.0) -> 50000
